<?xml version="1.0"?>
<sdf version="1.4">
   <model name="simple_bot">
      <static>false</static>
      <link name="chassis">
         <pose>0 0 .1 0 0 0</pose>
         <inertial>
            <!--m-->
            <mass>0.008</mass>
            <inertia>
               <!--ixx = 1/12*m*(w*w+h*h), iyy = 1/12*m*(l*l+h*h), izz = 1/12*m*(l*l+w*w)-->
               <ixx>0.000033333</ixx>
               <ixy>0</ixy>
               <ixz>0</ixz>
               <iyy>0.000113333</iyy>
               <iyz>0</iyz>
               <izz>0.000133333</izz>
            </inertia>
         </inertial>
         <collision name="collision">
            <geometry>
               <box>
                  <!--l w h-->
                  <size>.4 .2 .1</size>
               </box>
            </geometry>
         </collision>
         <visual name="visual">
            <geometry>
               <box>
                  <size>.4 .2 .1</size>
               </box>
            </geometry>
         </visual>         
      </link>

      <link name="left_wheel">
         <pose>0.1 0.13 0.1 0 1.5707 1.5707</pose>
         <inertial>
            <!--m-->
            <mass>0.001570796</mass>
            <inertia>
               <!--ixx = 1/12*m*(3*r*r+l*l), iyy = 1/12*m*(3*r*r+l*l), izz = 1/2*m*(r*r)-->
               <ixx>0.000004254</ixx>
               <ixy>0</ixy>
               <ixz>0</ixz>
               <iyy>0.000004254</iyy>
               <iyz>0</iyz>
               <izz>0.000007854</izz>
            </inertia>
         </inertial>
         <collision name="collision">
            <geometry>
               <cylinder>
                  <!--r l-->
                  <radius>.1</radius>
                  <length>.05</length>
               </cylinder>
            </geometry>
            <surface>
               <friction>
                  <ode>
                     <mu>1</mu>
                     <mu2>1</mu2>
                     <slip1>0</slip1>
                     <slip2>0</slip2>
                  </ode>
               </friction>
            </surface>
         </collision>
         <visual name="visual">
            <geometry>
               <cylinder>
                  <radius>.1</radius>
                  <length>.05</length>
               </cylinder>
            </geometry>
         </visual>
      </link>

      <link name="right_wheel">
         <pose>0.1 -0.13 0.1 0 1.5707 1.5707</pose>
         <inertial>
            <!--m-->
            <mass>0.001570796</mass>
            <inertia>
               <!--ixx = 1/12*m*(3*r*r+l*l), iyy = 1/12*m*(3*r*r+l*l), izz = 1/2*m*(r*r)-->
               <ixx>0.000004254</ixx>
               <ixy>0</ixy>
               <ixz>0</ixz>
               <iyy>0.000004254</iyy>
               <iyz>0</iyz>
               <izz>0.000007854</izz>
            </inertia>
         </inertial>
         <collision name="collision">
            <geometry>
               <cylinder>
                  <!--r l-->
                  <radius>.1</radius>
                  <length>.05</length>
               </cylinder>
            </geometry>
            <surface>
               <friction>
                  <ode>
                     <mu>1</mu>
                     <mu2>1</mu2>
                     <slip1>0</slip1>
                     <slip2>0</slip2>
                  </ode>
               </friction>
            </surface>
         </collision>
         <visual name="visual">
            <geometry>
               <cylinder>
                  <radius>.1</radius>
                  <length>.05</length>
               </cylinder>
            </geometry>
         </visual>
      </link>

      <link name='caster'>
         <pose>-0.15 0 0.05 0 0 0</pose>
         <inertial>
            <!--m-->
            <mass>0.00418879</mass>
            <inertia>
               <!--ixx = 2/5*m*r*r, iyy = 2/5*m*r*r, izz = 2/5*m*r*r-->
               <ixx>0.000016755</ixx>
               <ixy>0</ixy>
               <ixz>0</ixz>
               <iyy>0.000016755</iyy>
               <iyz>0</iyz>
               <izz>0.000016755</izz>
            </inertia>
         </inertial>
         <collision name="collision">
            <geometry>
               <sphere>
                  <!--r-->
                  <radius>.05</radius>
               </sphere>
            </geometry>
            <surface>
               <friction>
                  <ode>
                     <mu>0</mu>
                     <mu2>0</mu2>
                     <slip1>1.0</slip1>
                     <slip2>1.0</slip2>
                  </ode>
               </friction>
            </surface>
         </collision>
         <visual name="visual">
            <geometry>
               <sphere>
                  <radius>.05</radius>
               </sphere>
            </geometry>
         </visual>
      </link>

      <joint type="revolute" name="left_wheel_hinge">
         <pose>0 0 -0.03 0 0 0</pose>
         <child>left_wheel</child>
         <parent>chassis</parent>
         <axis>
            <xyz>0 1 0</xyz>
         </axis>
      </joint>

      <joint type="revolute" name="right_wheel_hinge">
         <pose>0 0 0.03 0 0 0</pose>
         <child>right_wheel</child>
         <parent>chassis</parent>
         <axis>
            <xyz>0 1 0</xyz>
         </axis>
      </joint>

      <joint name='caster_wheel' type='fixed'>
         <parent>chassis</parent>
         <child>caster</child>
      </joint>

      <plugin name='diff_drive' filename='libgazebo_ros_diff_drive.so'>

         <!-- wheels -->
         <left_joint>left_wheel_hinge</left_joint>
         <right_joint>right_wheel_hinge</right_joint>

         <!-- kinematics -->
         <wheel_separation>0.26</wheel_separation>
         <wheel_diameter>0.2</wheel_diameter>

         <!-- limits -->
         <max_wheel_torque>20</max_wheel_torque>
         <max_wheel_acceleration>1.0</max_wheel_acceleration>

         <!-- output -->
         <publish_odom>true</publish_odom>
         <publish_odom_tf>true</publish_odom_tf>
         <publish_wheel_tf>true</publish_wheel_tf>

         <robot_base_frame>chassis</robot_base_frame>

      </plugin>

   </model>
</sdf>