<?xml version="1.0"?>
<sdf version="1.4">
   <!--Model that contains the bot-->
   <model name="simple_bot">
      <!--Bot is moving so set static to false-->
      <static>false</static>
      <!--Chassis Link-->
      <link name="chassis">
         <!--x y z roll pitch yaw-->
         <pose>0 0 .1 0 0 0</pose>
         <!--Box around which collision can occur-->
         <collision name="collision">
            <geometry>
               <box>
                  <!--l w h-->
                  <size>.4 .2 .1</size>
               </box>
            </geometry>
         </collision>
         <!--Box which is actually seen in simulation-->
         <visual name="visual">
            <geometry>
               <box>
                  <!--l w h-->
                  <size>.4 .2 .1</size>
               </box>
            </geometry>
         </visual>
         <!--Creation of the caster wheel-->
         <collision name="caster_collision">
            <!--x y z roll pitch yaw-->
            <pose>-0.15 0 -0.05 0 0 0</pose>
            <geometry>
               <sphere>
                  <radius>.05</radius>
               </sphere>
            </geometry>
            <surface>
               <friction>
                  <ode>
                     <!-- Friction coefficient for the first friction direction-->
                     <mu>0</mu>
                     <!-- Friction coefficient for the second friction direction-->
                     <mu2>0</mu2>
                     <!-- Coefficients for slip-->
                     <slip1>1.0</slip1>
                     <slip2>1.0</slip2>
                  </ode>
               </friction>
            </surface>
         </collision>
         <visual name="caster_visual">
            <!--x y z roll pitch yaw-->
            <pose>-0.15 0 -0.05 0 0 0</pose>
            <geometry>
               <sphere>
                  <radius>.05</radius>
               </sphere>
            </geometry>
         </visual>
      </link>
      <!--Left Wheel Link-->
      <link name="left_wheel">
         <!--x y z roll pitch yaw-->
         <pose>0.1 0.13 0.1 0 1.5707 1.5707</pose>
         <collision name="collision">
            <geometry>
               <cylinder>
                  <radius>.1</radius>
                  <length>.05</length>
               </cylinder>
            </geometry>
         </collision>
         <visual name="visual">
            <geometry>
               <cylinder>
                  <radius>.1</radius>
                  <length>.05</length>
               </cylinder>
            </geometry>
         </visual>
      </link>
      <!--Right Wheel Link-->
      <link name="right_wheel">
         <!--x y z roll pitch yaw-->
         <pose>0.1 -0.13 0.1 0 1.5707 1.5707</pose>
         <collision name="collision">
            <geometry>
               <cylinder>
                  <radius>.1</radius>
                  <length>.05</length>
               </cylinder>
            </geometry>
         </collision>
         <visual name="visual">
            <geometry>
               <cylinder>
                  <radius>.1</radius>
                  <length>.05</length>
               </cylinder>
            </geometry>
         </visual>
      </link>
      <!--Definition of a joint for the left wheel-->
      <joint type="revolute" name="left_wheel_hinge">
         <!--x y z roll pitch yaw-->
         <pose>0 0 -0.03 0 0 0</pose>
         <child>left_wheel</child>
         <parent>chassis</parent>
         <axis>
            <xyz>0 1 0</xyz>
         </axis>
      </joint>
      <!--Definition of a joint for the right wheel-->
      <joint type="revolute" name="right_wheel_hinge">
         <!--x y z roll pitch yaw-->
         <pose>0 0 0.03 0 0 0</pose>
         <child>right_wheel</child>
         <parent>chassis</parent>
         <axis>
            <xyz>0 1 0</xyz>
         </axis>
      </joint>
   </model>
</sdf>
